<?xml version="1.0" encoding="UTF-8"?>
<testng-results skipped="0" failed="14" ignored="0" total="25" passed="11">
  <reporter-output>
  </reporter-output>
  <suite name="Default suite" duration-ms="113" started-at="2022-06-06T19:49:14 GMT+07:00" finished-at="2022-06-06T19:49:14 GMT+07:00">
    <groups>
    </groups>
    <test name="Default test" duration-ms="113" started-at="2022-06-06T19:49:14 GMT+07:00" finished-at="2022-06-06T19:49:14 GMT+07:00">
      <class name="online_tusur.unit_online_tusur.FactoryStydentTest">
        <test-method status="FAIL" signature="test1()[pri:0, instance:online_tusur.unit_online_tusur.FactoryStydentTest@1f57539, instance params:[online_tusur.unit_online_tusur.Student@6043cd28]]" name="test1" duration-ms="54" started-at="2022-06-06T19:49:14 GMT+07:00" finished-at="2022-06-06T19:49:14 GMT+07:00">
          <exception class="org.opentest4j.AssertionFailedError">
            <message>
              <![CDATA[expected: <50> but was: <18>]]>
            </message>
            <full-stacktrace>
              <![CDATA[org.opentest4j.AssertionFailedError: expected: <50> but was: <18>
at org.junit.jupiter.api.AssertionUtils.fail(AssertionUtils.java:55)
at org.junit.jupiter.api.AssertionUtils.failNotEqual(AssertionUtils.java:62)
at org.junit.jupiter.api.AssertEquals.assertEquals(AssertEquals.java:150)
at org.junit.jupiter.api.AssertEquals.assertEquals(AssertEquals.java:145)
at org.junit.jupiter.api.Assertions.assertEquals(Assertions.java:510)
at online_tusur.unit_online_tusur.FactoryStydentTest.test1(FactoryStydentTest.java:31)
at sun.reflect.NativeMethodAccessorImpl.invoke0(Native Method)
at sun.reflect.NativeMethodAccessorImpl.invoke(Unknown Source)
at sun.reflect.DelegatingMethodAccessorImpl.invoke(Unknown Source)
at java.lang.reflect.Method.invoke(Unknown Source)
at org.testng.internal.MethodInvocationHelper.invokeMethod(MethodInvocationHelper.java:133)
at org.testng.internal.TestInvoker.invokeMethod(TestInvoker.java:598)
at org.testng.internal.TestInvoker.invokeTestMethod(TestInvoker.java:173)
at org.testng.internal.MethodRunner.runInSequence(MethodRunner.java:46)
at org.testng.internal.TestInvoker$MethodInvocationAgent.invoke(TestInvoker.java:824)
at org.testng.internal.TestInvoker.invokeTestMethods(TestInvoker.java:146)
at org.testng.internal.TestMethodWorker.invokeTestMethods(TestMethodWorker.java:146)
at org.testng.internal.TestMethodWorker.run(TestMethodWorker.java:128)
at java.util.ArrayList.forEach(Unknown Source)
at org.testng.TestRunner.privateRun(TestRunner.java:794)
at org.testng.TestRunner.run(TestRunner.java:596)
at org.testng.SuiteRunner.runTest(SuiteRunner.java:377)
at org.testng.SuiteRunner.runSequentially(SuiteRunner.java:371)
at org.testng.SuiteRunner.privateRun(SuiteRunner.java:332)
at org.testng.SuiteRunner.run(SuiteRunner.java:276)
at org.testng.SuiteRunnerWorker.runSuite(SuiteRunnerWorker.java:53)
at org.testng.SuiteRunnerWorker.run(SuiteRunnerWorker.java:96)
at org.testng.TestNG.runSuitesSequentially(TestNG.java:1212)
at org.testng.TestNG.runSuitesLocally(TestNG.java:1134)
at org.testng.TestNG.runSuites(TestNG.java:1063)
at org.testng.TestNG.run(TestNG.java:1031)
at org.testng.remote.AbstractRemoteTestNG.run(AbstractRemoteTestNG.java:115)
at org.testng.remote.RemoteTestNG.initAndRun(RemoteTestNG.java:251)
at org.testng.remote.RemoteTestNG.main(RemoteTestNG.java:77)
]]>
            </full-stacktrace>
          </exception> <!-- org.opentest4j.AssertionFailedError -->
          <reporter-output>
          </reporter-output>
        </test-method> <!-- test1 -->
        <test-method status="PASS" signature="test1()[pri:0, instance:online_tusur.unit_online_tusur.FactoryStydentTest@536aaa8d, instance params:[online_tusur.unit_online_tusur.Student@45820e51]]" name="test1" duration-ms="0" started-at="2022-06-06T19:49:14 GMT+07:00" finished-at="2022-06-06T19:49:14 GMT+07:00">
          <reporter-output>
          </reporter-output>
        </test-method> <!-- test1 -->
        <test-method status="PASS" signature="test1()[pri:0, instance:online_tusur.unit_online_tusur.FactoryStydentTest@59e5ddf, instance params:[online_tusur.unit_online_tusur.Student@7113b13f]]" name="test1" duration-ms="0" started-at="2022-06-06T19:49:14 GMT+07:00" finished-at="2022-06-06T19:49:14 GMT+07:00">
          <reporter-output>
          </reporter-output>
        </test-method> <!-- test1 -->
        <test-method status="PASS" signature="test1()[pri:0, instance:online_tusur.unit_online_tusur.FactoryStydentTest@76f2b07d, instance params:[online_tusur.unit_online_tusur.Student@cb51256]]" name="test1" duration-ms="0" started-at="2022-06-06T19:49:14 GMT+07:00" finished-at="2022-06-06T19:49:14 GMT+07:00">
          <reporter-output>
          </reporter-output>
        </test-method> <!-- test1 -->
        <test-method status="FAIL" signature="test1()[pri:0, instance:online_tusur.unit_online_tusur.FactoryStydentTest@e320068, instance params:[online_tusur.unit_online_tusur.Student@42d8062c]]" name="test1" duration-ms="0" started-at="2022-06-06T19:49:14 GMT+07:00" finished-at="2022-06-06T19:49:14 GMT+07:00">
          <exception class="org.opentest4j.AssertionFailedError">
            <message>
              <![CDATA[expected: <32> but was: <18>]]>
            </message>
            <full-stacktrace>
              <![CDATA[org.opentest4j.AssertionFailedError: expected: <32> but was: <18>
at org.junit.jupiter.api.AssertionUtils.fail(AssertionUtils.java:55)
at org.junit.jupiter.api.AssertionUtils.failNotEqual(AssertionUtils.java:62)
at org.junit.jupiter.api.AssertEquals.assertEquals(AssertEquals.java:150)
at org.junit.jupiter.api.AssertEquals.assertEquals(AssertEquals.java:145)
at org.junit.jupiter.api.Assertions.assertEquals(Assertions.java:510)
at online_tusur.unit_online_tusur.FactoryStydentTest.test1(FactoryStydentTest.java:31)
at sun.reflect.NativeMethodAccessorImpl.invoke0(Native Method)
at sun.reflect.NativeMethodAccessorImpl.invoke(Unknown Source)
at sun.reflect.DelegatingMethodAccessorImpl.invoke(Unknown Source)
at java.lang.reflect.Method.invoke(Unknown Source)
at org.testng.internal.MethodInvocationHelper.invokeMethod(MethodInvocationHelper.java:133)
at org.testng.internal.TestInvoker.invokeMethod(TestInvoker.java:598)
at org.testng.internal.TestInvoker.invokeTestMethod(TestInvoker.java:173)
at org.testng.internal.MethodRunner.runInSequence(MethodRunner.java:46)
at org.testng.internal.TestInvoker$MethodInvocationAgent.invoke(TestInvoker.java:824)
at org.testng.internal.TestInvoker.invokeTestMethods(TestInvoker.java:146)
at org.testng.internal.TestMethodWorker.invokeTestMethods(TestMethodWorker.java:146)
at org.testng.internal.TestMethodWorker.run(TestMethodWorker.java:128)
at java.util.ArrayList.forEach(Unknown Source)
at org.testng.TestRunner.privateRun(TestRunner.java:794)
at org.testng.TestRunner.run(TestRunner.java:596)
at org.testng.SuiteRunner.runTest(SuiteRunner.java:377)
at org.testng.SuiteRunner.runSequentially(SuiteRunner.java:371)
at org.testng.SuiteRunner.privateRun(SuiteRunner.java:332)
at org.testng.SuiteRunner.run(SuiteRunner.java:276)
at org.testng.SuiteRunnerWorker.runSuite(SuiteRunnerWorker.java:53)
at org.testng.SuiteRunnerWorker.run(SuiteRunnerWorker.java:96)
at org.testng.TestNG.runSuitesSequentially(TestNG.java:1212)
at org.testng.TestNG.runSuitesLocally(TestNG.java:1134)
at org.testng.TestNG.runSuites(TestNG.java:1063)
at org.testng.TestNG.run(TestNG.java:1031)
at org.testng.remote.AbstractRemoteTestNG.run(AbstractRemoteTestNG.java:115)
at org.testng.remote.RemoteTestNG.initAndRun(RemoteTestNG.java:251)
at org.testng.remote.RemoteTestNG.main(RemoteTestNG.java:77)
]]>
            </full-stacktrace>
          </exception> <!-- org.opentest4j.AssertionFailedError -->
          <reporter-output>
          </reporter-output>
        </test-method> <!-- test1 -->
        <test-method status="FAIL" signature="test2()[pri:0, instance:online_tusur.unit_online_tusur.FactoryStydentTest@1f57539, instance params:[online_tusur.unit_online_tusur.Student@6043cd28]]" name="test2" duration-ms="0" started-at="2022-06-06T19:49:14 GMT+07:00" finished-at="2022-06-06T19:49:14 GMT+07:00">
          <exception class="org.opentest4j.AssertionFailedError">
            <message>
              <![CDATA[expected: <50> but was: <32>]]>
            </message>
            <full-stacktrace>
              <![CDATA[org.opentest4j.AssertionFailedError: expected: <50> but was: <32>
at org.junit.jupiter.api.AssertionUtils.fail(AssertionUtils.java:55)
at org.junit.jupiter.api.AssertionUtils.failNotEqual(AssertionUtils.java:62)
at org.junit.jupiter.api.AssertEquals.assertEquals(AssertEquals.java:150)
at org.junit.jupiter.api.AssertEquals.assertEquals(AssertEquals.java:145)
at org.junit.jupiter.api.Assertions.assertEquals(Assertions.java:510)
at online_tusur.unit_online_tusur.FactoryStydentTest.test2(FactoryStydentTest.java:37)
at sun.reflect.NativeMethodAccessorImpl.invoke0(Native Method)
at sun.reflect.NativeMethodAccessorImpl.invoke(Unknown Source)
at sun.reflect.DelegatingMethodAccessorImpl.invoke(Unknown Source)
at java.lang.reflect.Method.invoke(Unknown Source)
at org.testng.internal.MethodInvocationHelper.invokeMethod(MethodInvocationHelper.java:133)
at org.testng.internal.TestInvoker.invokeMethod(TestInvoker.java:598)
at org.testng.internal.TestInvoker.invokeTestMethod(TestInvoker.java:173)
at org.testng.internal.MethodRunner.runInSequence(MethodRunner.java:46)
at org.testng.internal.TestInvoker$MethodInvocationAgent.invoke(TestInvoker.java:824)
at org.testng.internal.TestInvoker.invokeTestMethods(TestInvoker.java:146)
at org.testng.internal.TestMethodWorker.invokeTestMethods(TestMethodWorker.java:146)
at org.testng.internal.TestMethodWorker.run(TestMethodWorker.java:128)
at java.util.ArrayList.forEach(Unknown Source)
at org.testng.TestRunner.privateRun(TestRunner.java:794)
at org.testng.TestRunner.run(TestRunner.java:596)
at org.testng.SuiteRunner.runTest(SuiteRunner.java:377)
at org.testng.SuiteRunner.runSequentially(SuiteRunner.java:371)
at org.testng.SuiteRunner.privateRun(SuiteRunner.java:332)
at org.testng.SuiteRunner.run(SuiteRunner.java:276)
at org.testng.SuiteRunnerWorker.runSuite(SuiteRunnerWorker.java:53)
at org.testng.SuiteRunnerWorker.run(SuiteRunnerWorker.java:96)
at org.testng.TestNG.runSuitesSequentially(TestNG.java:1212)
at org.testng.TestNG.runSuitesLocally(TestNG.java:1134)
at org.testng.TestNG.runSuites(TestNG.java:1063)
at org.testng.TestNG.run(TestNG.java:1031)
at org.testng.remote.AbstractRemoteTestNG.run(AbstractRemoteTestNG.java:115)
at org.testng.remote.RemoteTestNG.initAndRun(RemoteTestNG.java:251)
at org.testng.remote.RemoteTestNG.main(RemoteTestNG.java:77)
]]>
            </full-stacktrace>
          </exception> <!-- org.opentest4j.AssertionFailedError -->
          <reporter-output>
          </reporter-output>
        </test-method> <!-- test2 -->
        <test-method status="FAIL" signature="test2()[pri:0, instance:online_tusur.unit_online_tusur.FactoryStydentTest@536aaa8d, instance params:[online_tusur.unit_online_tusur.Student@45820e51]]" name="test2" duration-ms="1" started-at="2022-06-06T19:49:14 GMT+07:00" finished-at="2022-06-06T19:49:14 GMT+07:00">
          <exception class="org.opentest4j.AssertionFailedError">
            <message>
              <![CDATA[expected: <18> but was: <32>]]>
            </message>
            <full-stacktrace>
              <![CDATA[org.opentest4j.AssertionFailedError: expected: <18> but was: <32>
at org.junit.jupiter.api.AssertionUtils.fail(AssertionUtils.java:55)
at org.junit.jupiter.api.AssertionUtils.failNotEqual(AssertionUtils.java:62)
at org.junit.jupiter.api.AssertEquals.assertEquals(AssertEquals.java:150)
at org.junit.jupiter.api.AssertEquals.assertEquals(AssertEquals.java:145)
at org.junit.jupiter.api.Assertions.assertEquals(Assertions.java:510)
at online_tusur.unit_online_tusur.FactoryStydentTest.test2(FactoryStydentTest.java:37)
at sun.reflect.NativeMethodAccessorImpl.invoke0(Native Method)
at sun.reflect.NativeMethodAccessorImpl.invoke(Unknown Source)
at sun.reflect.DelegatingMethodAccessorImpl.invoke(Unknown Source)
at java.lang.reflect.Method.invoke(Unknown Source)
at org.testng.internal.MethodInvocationHelper.invokeMethod(MethodInvocationHelper.java:133)
at org.testng.internal.TestInvoker.invokeMethod(TestInvoker.java:598)
at org.testng.internal.TestInvoker.invokeTestMethod(TestInvoker.java:173)
at org.testng.internal.MethodRunner.runInSequence(MethodRunner.java:46)
at org.testng.internal.TestInvoker$MethodInvocationAgent.invoke(TestInvoker.java:824)
at org.testng.internal.TestInvoker.invokeTestMethods(TestInvoker.java:146)
at org.testng.internal.TestMethodWorker.invokeTestMethods(TestMethodWorker.java:146)
at org.testng.internal.TestMethodWorker.run(TestMethodWorker.java:128)
at java.util.ArrayList.forEach(Unknown Source)
at org.testng.TestRunner.privateRun(TestRunner.java:794)
at org.testng.TestRunner.run(TestRunner.java:596)
at org.testng.SuiteRunner.runTest(SuiteRunner.java:377)
at org.testng.SuiteRunner.runSequentially(SuiteRunner.java:371)
at org.testng.SuiteRunner.privateRun(SuiteRunner.java:332)
at org.testng.SuiteRunner.run(SuiteRunner.java:276)
at org.testng.SuiteRunnerWorker.runSuite(SuiteRunnerWorker.java:53)
at org.testng.SuiteRunnerWorker.run(SuiteRunnerWorker.java:96)
at org.testng.TestNG.runSuitesSequentially(TestNG.java:1212)
at org.testng.TestNG.runSuitesLocally(TestNG.java:1134)
at org.testng.TestNG.runSuites(TestNG.java:1063)
at org.testng.TestNG.run(TestNG.java:1031)
at org.testng.remote.AbstractRemoteTestNG.run(AbstractRemoteTestNG.java:115)
at org.testng.remote.RemoteTestNG.initAndRun(RemoteTestNG.java:251)
at org.testng.remote.RemoteTestNG.main(RemoteTestNG.java:77)
]]>
            </full-stacktrace>
          </exception> <!-- org.opentest4j.AssertionFailedError -->
          <reporter-output>
          </reporter-output>
        </test-method> <!-- test2 -->
        <test-method status="FAIL" signature="test2()[pri:0, instance:online_tusur.unit_online_tusur.FactoryStydentTest@59e5ddf, instance params:[online_tusur.unit_online_tusur.Student@7113b13f]]" name="test2" duration-ms="1" started-at="2022-06-06T19:49:14 GMT+07:00" finished-at="2022-06-06T19:49:14 GMT+07:00">
          <exception class="org.opentest4j.AssertionFailedError">
            <message>
              <![CDATA[expected: <18> but was: <32>]]>
            </message>
            <full-stacktrace>
              <![CDATA[org.opentest4j.AssertionFailedError: expected: <18> but was: <32>
at org.junit.jupiter.api.AssertionUtils.fail(AssertionUtils.java:55)
at org.junit.jupiter.api.AssertionUtils.failNotEqual(AssertionUtils.java:62)
at org.junit.jupiter.api.AssertEquals.assertEquals(AssertEquals.java:150)
at org.junit.jupiter.api.AssertEquals.assertEquals(AssertEquals.java:145)
at org.junit.jupiter.api.Assertions.assertEquals(Assertions.java:510)
at online_tusur.unit_online_tusur.FactoryStydentTest.test2(FactoryStydentTest.java:37)
at sun.reflect.NativeMethodAccessorImpl.invoke0(Native Method)
at sun.reflect.NativeMethodAccessorImpl.invoke(Unknown Source)
at sun.reflect.DelegatingMethodAccessorImpl.invoke(Unknown Source)
at java.lang.reflect.Method.invoke(Unknown Source)
at org.testng.internal.MethodInvocationHelper.invokeMethod(MethodInvocationHelper.java:133)
at org.testng.internal.TestInvoker.invokeMethod(TestInvoker.java:598)
at org.testng.internal.TestInvoker.invokeTestMethod(TestInvoker.java:173)
at org.testng.internal.MethodRunner.runInSequence(MethodRunner.java:46)
at org.testng.internal.TestInvoker$MethodInvocationAgent.invoke(TestInvoker.java:824)
at org.testng.internal.TestInvoker.invokeTestMethods(TestInvoker.java:146)
at org.testng.internal.TestMethodWorker.invokeTestMethods(TestMethodWorker.java:146)
at org.testng.internal.TestMethodWorker.run(TestMethodWorker.java:128)
at java.util.ArrayList.forEach(Unknown Source)
at org.testng.TestRunner.privateRun(TestRunner.java:794)
at org.testng.TestRunner.run(TestRunner.java:596)
at org.testng.SuiteRunner.runTest(SuiteRunner.java:377)
at org.testng.SuiteRunner.runSequentially(SuiteRunner.java:371)
at org.testng.SuiteRunner.privateRun(SuiteRunner.java:332)
at org.testng.SuiteRunner.run(SuiteRunner.java:276)
at org.testng.SuiteRunnerWorker.runSuite(SuiteRunnerWorker.java:53)
at org.testng.SuiteRunnerWorker.run(SuiteRunnerWorker.java:96)
at org.testng.TestNG.runSuitesSequentially(TestNG.java:1212)
at org.testng.TestNG.runSuitesLocally(TestNG.java:1134)
at org.testng.TestNG.runSuites(TestNG.java:1063)
at org.testng.TestNG.run(TestNG.java:1031)
at org.testng.remote.AbstractRemoteTestNG.run(AbstractRemoteTestNG.java:115)
at org.testng.remote.RemoteTestNG.initAndRun(RemoteTestNG.java:251)
at org.testng.remote.RemoteTestNG.main(RemoteTestNG.java:77)
]]>
            </full-stacktrace>
          </exception> <!-- org.opentest4j.AssertionFailedError -->
          <reporter-output>
          </reporter-output>
        </test-method> <!-- test2 -->
        <test-method status="FAIL" signature="test2()[pri:0, instance:online_tusur.unit_online_tusur.FactoryStydentTest@76f2b07d, instance params:[online_tusur.unit_online_tusur.Student@cb51256]]" name="test2" duration-ms="0" started-at="2022-06-06T19:49:14 GMT+07:00" finished-at="2022-06-06T19:49:14 GMT+07:00">
          <exception class="org.opentest4j.AssertionFailedError">
            <message>
              <![CDATA[expected: <18> but was: <32>]]>
            </message>
            <full-stacktrace>
              <![CDATA[org.opentest4j.AssertionFailedError: expected: <18> but was: <32>
at org.junit.jupiter.api.AssertionUtils.fail(AssertionUtils.java:55)
at org.junit.jupiter.api.AssertionUtils.failNotEqual(AssertionUtils.java:62)
at org.junit.jupiter.api.AssertEquals.assertEquals(AssertEquals.java:150)
at org.junit.jupiter.api.AssertEquals.assertEquals(AssertEquals.java:145)
at org.junit.jupiter.api.Assertions.assertEquals(Assertions.java:510)
at online_tusur.unit_online_tusur.FactoryStydentTest.test2(FactoryStydentTest.java:37)
at sun.reflect.NativeMethodAccessorImpl.invoke0(Native Method)
at sun.reflect.NativeMethodAccessorImpl.invoke(Unknown Source)
at sun.reflect.DelegatingMethodAccessorImpl.invoke(Unknown Source)
at java.lang.reflect.Method.invoke(Unknown Source)
at org.testng.internal.MethodInvocationHelper.invokeMethod(MethodInvocationHelper.java:133)
at org.testng.internal.TestInvoker.invokeMethod(TestInvoker.java:598)
at org.testng.internal.TestInvoker.invokeTestMethod(TestInvoker.java:173)
at org.testng.internal.MethodRunner.runInSequence(MethodRunner.java:46)
at org.testng.internal.TestInvoker$MethodInvocationAgent.invoke(TestInvoker.java:824)
at org.testng.internal.TestInvoker.invokeTestMethods(TestInvoker.java:146)
at org.testng.internal.TestMethodWorker.invokeTestMethods(TestMethodWorker.java:146)
at org.testng.internal.TestMethodWorker.run(TestMethodWorker.java:128)
at java.util.ArrayList.forEach(Unknown Source)
at org.testng.TestRunner.privateRun(TestRunner.java:794)
at org.testng.TestRunner.run(TestRunner.java:596)
at org.testng.SuiteRunner.runTest(SuiteRunner.java:377)
at org.testng.SuiteRunner.runSequentially(SuiteRunner.java:371)
at org.testng.SuiteRunner.privateRun(SuiteRunner.java:332)
at org.testng.SuiteRunner.run(SuiteRunner.java:276)
at org.testng.SuiteRunnerWorker.runSuite(SuiteRunnerWorker.java:53)
at org.testng.SuiteRunnerWorker.run(SuiteRunnerWorker.java:96)
at org.testng.TestNG.runSuitesSequentially(TestNG.java:1212)
at org.testng.TestNG.runSuitesLocally(TestNG.java:1134)
at org.testng.TestNG.runSuites(TestNG.java:1063)
at org.testng.TestNG.run(TestNG.java:1031)
at org.testng.remote.AbstractRemoteTestNG.run(AbstractRemoteTestNG.java:115)
at org.testng.remote.RemoteTestNG.initAndRun(RemoteTestNG.java:251)
at org.testng.remote.RemoteTestNG.main(RemoteTestNG.java:77)
]]>
            </full-stacktrace>
          </exception> <!-- org.opentest4j.AssertionFailedError -->
          <reporter-output>
          </reporter-output>
        </test-method> <!-- test2 -->
        <test-method status="PASS" signature="test2()[pri:0, instance:online_tusur.unit_online_tusur.FactoryStydentTest@e320068, instance params:[online_tusur.unit_online_tusur.Student@42d8062c]]" name="test2" duration-ms="0" started-at="2022-06-06T19:49:14 GMT+07:00" finished-at="2022-06-06T19:49:14 GMT+07:00">
          <reporter-output>
          </reporter-output>
        </test-method> <!-- test2 -->
        <test-method status="PASS" signature="test3()[pri:0, instance:online_tusur.unit_online_tusur.FactoryStydentTest@1f57539, instance params:[online_tusur.unit_online_tusur.Student@6043cd28]]" name="test3" duration-ms="0" started-at="2022-06-06T19:49:14 GMT+07:00" finished-at="2022-06-06T19:49:14 GMT+07:00">
          <reporter-output>
          </reporter-output>
        </test-method> <!-- test3 -->
        <test-method status="FAIL" signature="test3()[pri:0, instance:online_tusur.unit_online_tusur.FactoryStydentTest@536aaa8d, instance params:[online_tusur.unit_online_tusur.Student@45820e51]]" name="test3" duration-ms="0" started-at="2022-06-06T19:49:14 GMT+07:00" finished-at="2022-06-06T19:49:14 GMT+07:00">
          <exception class="org.opentest4j.AssertionFailedError">
            <message>
              <![CDATA[expected: <18> but was: <50>]]>
            </message>
            <full-stacktrace>
              <![CDATA[org.opentest4j.AssertionFailedError: expected: <18> but was: <50>
at org.junit.jupiter.api.AssertionUtils.fail(AssertionUtils.java:55)
at org.junit.jupiter.api.AssertionUtils.failNotEqual(AssertionUtils.java:62)
at org.junit.jupiter.api.AssertEquals.assertEquals(AssertEquals.java:150)
at org.junit.jupiter.api.AssertEquals.assertEquals(AssertEquals.java:145)
at org.junit.jupiter.api.Assertions.assertEquals(Assertions.java:510)
at online_tusur.unit_online_tusur.FactoryStydentTest.test3(FactoryStydentTest.java:44)
at sun.reflect.NativeMethodAccessorImpl.invoke0(Native Method)
at sun.reflect.NativeMethodAccessorImpl.invoke(Unknown Source)
at sun.reflect.DelegatingMethodAccessorImpl.invoke(Unknown Source)
at java.lang.reflect.Method.invoke(Unknown Source)
at org.testng.internal.MethodInvocationHelper.invokeMethod(MethodInvocationHelper.java:133)
at org.testng.internal.TestInvoker.invokeMethod(TestInvoker.java:598)
at org.testng.internal.TestInvoker.invokeTestMethod(TestInvoker.java:173)
at org.testng.internal.MethodRunner.runInSequence(MethodRunner.java:46)
at org.testng.internal.TestInvoker$MethodInvocationAgent.invoke(TestInvoker.java:824)
at org.testng.internal.TestInvoker.invokeTestMethods(TestInvoker.java:146)
at org.testng.internal.TestMethodWorker.invokeTestMethods(TestMethodWorker.java:146)
at org.testng.internal.TestMethodWorker.run(TestMethodWorker.java:128)
at java.util.ArrayList.forEach(Unknown Source)
at org.testng.TestRunner.privateRun(TestRunner.java:794)
at org.testng.TestRunner.run(TestRunner.java:596)
at org.testng.SuiteRunner.runTest(SuiteRunner.java:377)
at org.testng.SuiteRunner.runSequentially(SuiteRunner.java:371)
at org.testng.SuiteRunner.privateRun(SuiteRunner.java:332)
at org.testng.SuiteRunner.run(SuiteRunner.java:276)
at org.testng.SuiteRunnerWorker.runSuite(SuiteRunnerWorker.java:53)
at org.testng.SuiteRunnerWorker.run(SuiteRunnerWorker.java:96)
at org.testng.TestNG.runSuitesSequentially(TestNG.java:1212)
at org.testng.TestNG.runSuitesLocally(TestNG.java:1134)
at org.testng.TestNG.runSuites(TestNG.java:1063)
at org.testng.TestNG.run(TestNG.java:1031)
at org.testng.remote.AbstractRemoteTestNG.run(AbstractRemoteTestNG.java:115)
at org.testng.remote.RemoteTestNG.initAndRun(RemoteTestNG.java:251)
at org.testng.remote.RemoteTestNG.main(RemoteTestNG.java:77)
]]>
            </full-stacktrace>
          </exception> <!-- org.opentest4j.AssertionFailedError -->
          <reporter-output>
          </reporter-output>
        </test-method> <!-- test3 -->
        <test-method status="FAIL" signature="test3()[pri:0, instance:online_tusur.unit_online_tusur.FactoryStydentTest@59e5ddf, instance params:[online_tusur.unit_online_tusur.Student@7113b13f]]" name="test3" duration-ms="0" started-at="2022-06-06T19:49:14 GMT+07:00" finished-at="2022-06-06T19:49:14 GMT+07:00">
          <exception class="org.opentest4j.AssertionFailedError">
            <message>
              <![CDATA[expected: <18> but was: <50>]]>
            </message>
            <full-stacktrace>
              <![CDATA[org.opentest4j.AssertionFailedError: expected: <18> but was: <50>
at org.junit.jupiter.api.AssertionUtils.fail(AssertionUtils.java:55)
at org.junit.jupiter.api.AssertionUtils.failNotEqual(AssertionUtils.java:62)
at org.junit.jupiter.api.AssertEquals.assertEquals(AssertEquals.java:150)
at org.junit.jupiter.api.AssertEquals.assertEquals(AssertEquals.java:145)
at org.junit.jupiter.api.Assertions.assertEquals(Assertions.java:510)
at online_tusur.unit_online_tusur.FactoryStydentTest.test3(FactoryStydentTest.java:44)
at sun.reflect.NativeMethodAccessorImpl.invoke0(Native Method)
at sun.reflect.NativeMethodAccessorImpl.invoke(Unknown Source)
at sun.reflect.DelegatingMethodAccessorImpl.invoke(Unknown Source)
at java.lang.reflect.Method.invoke(Unknown Source)
at org.testng.internal.MethodInvocationHelper.invokeMethod(MethodInvocationHelper.java:133)
at org.testng.internal.TestInvoker.invokeMethod(TestInvoker.java:598)
at org.testng.internal.TestInvoker.invokeTestMethod(TestInvoker.java:173)
at org.testng.internal.MethodRunner.runInSequence(MethodRunner.java:46)
at org.testng.internal.TestInvoker$MethodInvocationAgent.invoke(TestInvoker.java:824)
at org.testng.internal.TestInvoker.invokeTestMethods(TestInvoker.java:146)
at org.testng.internal.TestMethodWorker.invokeTestMethods(TestMethodWorker.java:146)
at org.testng.internal.TestMethodWorker.run(TestMethodWorker.java:128)
at java.util.ArrayList.forEach(Unknown Source)
at org.testng.TestRunner.privateRun(TestRunner.java:794)
at org.testng.TestRunner.run(TestRunner.java:596)
at org.testng.SuiteRunner.runTest(SuiteRunner.java:377)
at org.testng.SuiteRunner.runSequentially(SuiteRunner.java:371)
at org.testng.SuiteRunner.privateRun(SuiteRunner.java:332)
at org.testng.SuiteRunner.run(SuiteRunner.java:276)
at org.testng.SuiteRunnerWorker.runSuite(SuiteRunnerWorker.java:53)
at org.testng.SuiteRunnerWorker.run(SuiteRunnerWorker.java:96)
at org.testng.TestNG.runSuitesSequentially(TestNG.java:1212)
at org.testng.TestNG.runSuitesLocally(TestNG.java:1134)
at org.testng.TestNG.runSuites(TestNG.java:1063)
at org.testng.TestNG.run(TestNG.java:1031)
at org.testng.remote.AbstractRemoteTestNG.run(AbstractRemoteTestNG.java:115)
at org.testng.remote.RemoteTestNG.initAndRun(RemoteTestNG.java:251)
at org.testng.remote.RemoteTestNG.main(RemoteTestNG.java:77)
]]>
            </full-stacktrace>
          </exception> <!-- org.opentest4j.AssertionFailedError -->
          <reporter-output>
          </reporter-output>
        </test-method> <!-- test3 -->
        <test-method status="FAIL" signature="test3()[pri:0, instance:online_tusur.unit_online_tusur.FactoryStydentTest@76f2b07d, instance params:[online_tusur.unit_online_tusur.Student@cb51256]]" name="test3" duration-ms="1" started-at="2022-06-06T19:49:14 GMT+07:00" finished-at="2022-06-06T19:49:14 GMT+07:00">
          <exception class="org.opentest4j.AssertionFailedError">
            <message>
              <![CDATA[expected: <18> but was: <50>]]>
            </message>
            <full-stacktrace>
              <![CDATA[org.opentest4j.AssertionFailedError: expected: <18> but was: <50>
at org.junit.jupiter.api.AssertionUtils.fail(AssertionUtils.java:55)
at org.junit.jupiter.api.AssertionUtils.failNotEqual(AssertionUtils.java:62)
at org.junit.jupiter.api.AssertEquals.assertEquals(AssertEquals.java:150)
at org.junit.jupiter.api.AssertEquals.assertEquals(AssertEquals.java:145)
at org.junit.jupiter.api.Assertions.assertEquals(Assertions.java:510)
at online_tusur.unit_online_tusur.FactoryStydentTest.test3(FactoryStydentTest.java:44)
at sun.reflect.NativeMethodAccessorImpl.invoke0(Native Method)
at sun.reflect.NativeMethodAccessorImpl.invoke(Unknown Source)
at sun.reflect.DelegatingMethodAccessorImpl.invoke(Unknown Source)
at java.lang.reflect.Method.invoke(Unknown Source)
at org.testng.internal.MethodInvocationHelper.invokeMethod(MethodInvocationHelper.java:133)
at org.testng.internal.TestInvoker.invokeMethod(TestInvoker.java:598)
at org.testng.internal.TestInvoker.invokeTestMethod(TestInvoker.java:173)
at org.testng.internal.MethodRunner.runInSequence(MethodRunner.java:46)
at org.testng.internal.TestInvoker$MethodInvocationAgent.invoke(TestInvoker.java:824)
at org.testng.internal.TestInvoker.invokeTestMethods(TestInvoker.java:146)
at org.testng.internal.TestMethodWorker.invokeTestMethods(TestMethodWorker.java:146)
at org.testng.internal.TestMethodWorker.run(TestMethodWorker.java:128)
at java.util.ArrayList.forEach(Unknown Source)
at org.testng.TestRunner.privateRun(TestRunner.java:794)
at org.testng.TestRunner.run(TestRunner.java:596)
at org.testng.SuiteRunner.runTest(SuiteRunner.java:377)
at org.testng.SuiteRunner.runSequentially(SuiteRunner.java:371)
at org.testng.SuiteRunner.privateRun(SuiteRunner.java:332)
at org.testng.SuiteRunner.run(SuiteRunner.java:276)
at org.testng.SuiteRunnerWorker.runSuite(SuiteRunnerWorker.java:53)
at org.testng.SuiteRunnerWorker.run(SuiteRunnerWorker.java:96)
at org.testng.TestNG.runSuitesSequentially(TestNG.java:1212)
at org.testng.TestNG.runSuitesLocally(TestNG.java:1134)
at org.testng.TestNG.runSuites(TestNG.java:1063)
at org.testng.TestNG.run(TestNG.java:1031)
at org.testng.remote.AbstractRemoteTestNG.run(AbstractRemoteTestNG.java:115)
at org.testng.remote.RemoteTestNG.initAndRun(RemoteTestNG.java:251)
at org.testng.remote.RemoteTestNG.main(RemoteTestNG.java:77)
]]>
            </full-stacktrace>
          </exception> <!-- org.opentest4j.AssertionFailedError -->
          <reporter-output>
          </reporter-output>
        </test-method> <!-- test3 -->
        <test-method status="FAIL" signature="test3()[pri:0, instance:online_tusur.unit_online_tusur.FactoryStydentTest@e320068, instance params:[online_tusur.unit_online_tusur.Student@42d8062c]]" name="test3" duration-ms="0" started-at="2022-06-06T19:49:14 GMT+07:00" finished-at="2022-06-06T19:49:14 GMT+07:00">
          <exception class="org.opentest4j.AssertionFailedError">
            <message>
              <![CDATA[expected: <32> but was: <50>]]>
            </message>
            <full-stacktrace>
              <![CDATA[org.opentest4j.AssertionFailedError: expected: <32> but was: <50>
at org.junit.jupiter.api.AssertionUtils.fail(AssertionUtils.java:55)
at org.junit.jupiter.api.AssertionUtils.failNotEqual(AssertionUtils.java:62)
at org.junit.jupiter.api.AssertEquals.assertEquals(AssertEquals.java:150)
at org.junit.jupiter.api.AssertEquals.assertEquals(AssertEquals.java:145)
at org.junit.jupiter.api.Assertions.assertEquals(Assertions.java:510)
at online_tusur.unit_online_tusur.FactoryStydentTest.test3(FactoryStydentTest.java:44)
at sun.reflect.NativeMethodAccessorImpl.invoke0(Native Method)
at sun.reflect.NativeMethodAccessorImpl.invoke(Unknown Source)
at sun.reflect.DelegatingMethodAccessorImpl.invoke(Unknown Source)
at java.lang.reflect.Method.invoke(Unknown Source)
at org.testng.internal.MethodInvocationHelper.invokeMethod(MethodInvocationHelper.java:133)
at org.testng.internal.TestInvoker.invokeMethod(TestInvoker.java:598)
at org.testng.internal.TestInvoker.invokeTestMethod(TestInvoker.java:173)
at org.testng.internal.MethodRunner.runInSequence(MethodRunner.java:46)
at org.testng.internal.TestInvoker$MethodInvocationAgent.invoke(TestInvoker.java:824)
at org.testng.internal.TestInvoker.invokeTestMethods(TestInvoker.java:146)
at org.testng.internal.TestMethodWorker.invokeTestMethods(TestMethodWorker.java:146)
at org.testng.internal.TestMethodWorker.run(TestMethodWorker.java:128)
at java.util.ArrayList.forEach(Unknown Source)
at org.testng.TestRunner.privateRun(TestRunner.java:794)
at org.testng.TestRunner.run(TestRunner.java:596)
at org.testng.SuiteRunner.runTest(SuiteRunner.java:377)
at org.testng.SuiteRunner.runSequentially(SuiteRunner.java:371)
at org.testng.SuiteRunner.privateRun(SuiteRunner.java:332)
at org.testng.SuiteRunner.run(SuiteRunner.java:276)
at org.testng.SuiteRunnerWorker.runSuite(SuiteRunnerWorker.java:53)
at org.testng.SuiteRunnerWorker.run(SuiteRunnerWorker.java:96)
at org.testng.TestNG.runSuitesSequentially(TestNG.java:1212)
at org.testng.TestNG.runSuitesLocally(TestNG.java:1134)
at org.testng.TestNG.runSuites(TestNG.java:1063)
at org.testng.TestNG.run(TestNG.java:1031)
at org.testng.remote.AbstractRemoteTestNG.run(AbstractRemoteTestNG.java:115)
at org.testng.remote.RemoteTestNG.initAndRun(RemoteTestNG.java:251)
at org.testng.remote.RemoteTestNG.main(RemoteTestNG.java:77)
]]>
            </full-stacktrace>
          </exception> <!-- org.opentest4j.AssertionFailedError -->
          <reporter-output>
          </reporter-output>
        </test-method> <!-- test3 -->
        <test-method status="PASS" signature="test4()[pri:0, instance:online_tusur.unit_online_tusur.FactoryStydentTest@1f57539, instance params:[online_tusur.unit_online_tusur.Student@6043cd28]]" name="test4" duration-ms="1" started-at="2022-06-06T19:49:14 GMT+07:00" finished-at="2022-06-06T19:49:14 GMT+07:00">
          <reporter-output>
          </reporter-output>
        </test-method> <!-- test4 -->
        <test-method status="FAIL" signature="test4()[pri:0, instance:online_tusur.unit_online_tusur.FactoryStydentTest@536aaa8d, instance params:[online_tusur.unit_online_tusur.Student@45820e51]]" name="test4" duration-ms="1" started-at="2022-06-06T19:49:14 GMT+07:00" finished-at="2022-06-06T19:49:14 GMT+07:00">
          <exception class="org.opentest4j.AssertionFailedError">
            <message>
              <![CDATA[expected: <Ivaaaaan> but was: <Ivan>]]>
            </message>
            <full-stacktrace>
              <![CDATA[org.opentest4j.AssertionFailedError: expected: <Ivaaaaan> but was: <Ivan>
at org.junit.jupiter.api.AssertionUtils.fail(AssertionUtils.java:55)
at org.junit.jupiter.api.AssertionUtils.failNotEqual(AssertionUtils.java:62)
at org.junit.jupiter.api.AssertEquals.assertEquals(AssertEquals.java:182)
at org.junit.jupiter.api.AssertEquals.assertEquals(AssertEquals.java:177)
at org.junit.jupiter.api.Assertions.assertEquals(Assertions.java:1124)
at online_tusur.unit_online_tusur.FactoryStydentTest.test4(FactoryStydentTest.java:51)
at sun.reflect.NativeMethodAccessorImpl.invoke0(Native Method)
at sun.reflect.NativeMethodAccessorImpl.invoke(Unknown Source)
at sun.reflect.DelegatingMethodAccessorImpl.invoke(Unknown Source)
at java.lang.reflect.Method.invoke(Unknown Source)
at org.testng.internal.MethodInvocationHelper.invokeMethod(MethodInvocationHelper.java:133)
at org.testng.internal.TestInvoker.invokeMethod(TestInvoker.java:598)
at org.testng.internal.TestInvoker.invokeTestMethod(TestInvoker.java:173)
at org.testng.internal.MethodRunner.runInSequence(MethodRunner.java:46)
at org.testng.internal.TestInvoker$MethodInvocationAgent.invoke(TestInvoker.java:824)
at org.testng.internal.TestInvoker.invokeTestMethods(TestInvoker.java:146)
at org.testng.internal.TestMethodWorker.invokeTestMethods(TestMethodWorker.java:146)
at org.testng.internal.TestMethodWorker.run(TestMethodWorker.java:128)
at java.util.ArrayList.forEach(Unknown Source)
at org.testng.TestRunner.privateRun(TestRunner.java:794)
at org.testng.TestRunner.run(TestRunner.java:596)
at org.testng.SuiteRunner.runTest(SuiteRunner.java:377)
at org.testng.SuiteRunner.runSequentially(SuiteRunner.java:371)
at org.testng.SuiteRunner.privateRun(SuiteRunner.java:332)
at org.testng.SuiteRunner.run(SuiteRunner.java:276)
at org.testng.SuiteRunnerWorker.runSuite(SuiteRunnerWorker.java:53)
at org.testng.SuiteRunnerWorker.run(SuiteRunnerWorker.java:96)
at org.testng.TestNG.runSuitesSequentially(TestNG.java:1212)
at org.testng.TestNG.runSuitesLocally(TestNG.java:1134)
at org.testng.TestNG.runSuites(TestNG.java:1063)
at org.testng.TestNG.run(TestNG.java:1031)
at org.testng.remote.AbstractRemoteTestNG.run(AbstractRemoteTestNG.java:115)
at org.testng.remote.RemoteTestNG.initAndRun(RemoteTestNG.java:251)
at org.testng.remote.RemoteTestNG.main(RemoteTestNG.java:77)
]]>
            </full-stacktrace>
          </exception> <!-- org.opentest4j.AssertionFailedError -->
          <reporter-output>
          </reporter-output>
        </test-method> <!-- test4 -->
        <test-method status="PASS" signature="test4()[pri:0, instance:online_tusur.unit_online_tusur.FactoryStydentTest@59e5ddf, instance params:[online_tusur.unit_online_tusur.Student@7113b13f]]" name="test4" duration-ms="1" started-at="2022-06-06T19:49:14 GMT+07:00" finished-at="2022-06-06T19:49:14 GMT+07:00">
          <reporter-output>
          </reporter-output>
        </test-method> <!-- test4 -->
        <test-method status="FAIL" signature="test4()[pri:0, instance:online_tusur.unit_online_tusur.FactoryStydentTest@76f2b07d, instance params:[online_tusur.unit_online_tusur.Student@cb51256]]" name="test4" duration-ms="1" started-at="2022-06-06T19:49:14 GMT+07:00" finished-at="2022-06-06T19:49:14 GMT+07:00">
          <exception class="org.opentest4j.AssertionFailedError">
            <message>
              <![CDATA[expected: <Ivaaaaan> but was: <Ivan>]]>
            </message>
            <full-stacktrace>
              <![CDATA[org.opentest4j.AssertionFailedError: expected: <Ivaaaaan> but was: <Ivan>
at org.junit.jupiter.api.AssertionUtils.fail(AssertionUtils.java:55)
at org.junit.jupiter.api.AssertionUtils.failNotEqual(AssertionUtils.java:62)
at org.junit.jupiter.api.AssertEquals.assertEquals(AssertEquals.java:182)
at org.junit.jupiter.api.AssertEquals.assertEquals(AssertEquals.java:177)
at org.junit.jupiter.api.Assertions.assertEquals(Assertions.java:1124)
at online_tusur.unit_online_tusur.FactoryStydentTest.test4(FactoryStydentTest.java:51)
at sun.reflect.NativeMethodAccessorImpl.invoke0(Native Method)
at sun.reflect.NativeMethodAccessorImpl.invoke(Unknown Source)
at sun.reflect.DelegatingMethodAccessorImpl.invoke(Unknown Source)
at java.lang.reflect.Method.invoke(Unknown Source)
at org.testng.internal.MethodInvocationHelper.invokeMethod(MethodInvocationHelper.java:133)
at org.testng.internal.TestInvoker.invokeMethod(TestInvoker.java:598)
at org.testng.internal.TestInvoker.invokeTestMethod(TestInvoker.java:173)
at org.testng.internal.MethodRunner.runInSequence(MethodRunner.java:46)
at org.testng.internal.TestInvoker$MethodInvocationAgent.invoke(TestInvoker.java:824)
at org.testng.internal.TestInvoker.invokeTestMethods(TestInvoker.java:146)
at org.testng.internal.TestMethodWorker.invokeTestMethods(TestMethodWorker.java:146)
at org.testng.internal.TestMethodWorker.run(TestMethodWorker.java:128)
at java.util.ArrayList.forEach(Unknown Source)
at org.testng.TestRunner.privateRun(TestRunner.java:794)
at org.testng.TestRunner.run(TestRunner.java:596)
at org.testng.SuiteRunner.runTest(SuiteRunner.java:377)
at org.testng.SuiteRunner.runSequentially(SuiteRunner.java:371)
at org.testng.SuiteRunner.privateRun(SuiteRunner.java:332)
at org.testng.SuiteRunner.run(SuiteRunner.java:276)
at org.testng.SuiteRunnerWorker.runSuite(SuiteRunnerWorker.java:53)
at org.testng.SuiteRunnerWorker.run(SuiteRunnerWorker.java:96)
at org.testng.TestNG.runSuitesSequentially(TestNG.java:1212)
at org.testng.TestNG.runSuitesLocally(TestNG.java:1134)
at org.testng.TestNG.runSuites(TestNG.java:1063)
at org.testng.TestNG.run(TestNG.java:1031)
at org.testng.remote.AbstractRemoteTestNG.run(AbstractRemoteTestNG.java:115)
at org.testng.remote.RemoteTestNG.initAndRun(RemoteTestNG.java:251)
at org.testng.remote.RemoteTestNG.main(RemoteTestNG.java:77)
]]>
            </full-stacktrace>
          </exception> <!-- org.opentest4j.AssertionFailedError -->
          <reporter-output>
          </reporter-output>
        </test-method> <!-- test4 -->
        <test-method status="PASS" signature="test4()[pri:0, instance:online_tusur.unit_online_tusur.FactoryStydentTest@e320068, instance params:[online_tusur.unit_online_tusur.Student@42d8062c]]" name="test4" duration-ms="0" started-at="2022-06-06T19:49:14 GMT+07:00" finished-at="2022-06-06T19:49:14 GMT+07:00">
          <reporter-output>
          </reporter-output>
        </test-method> <!-- test4 -->
        <test-method status="PASS" signature="test5()[pri:0, instance:online_tusur.unit_online_tusur.FactoryStydentTest@1f57539, instance params:[online_tusur.unit_online_tusur.Student@6043cd28]]" name="test5" duration-ms="0" started-at="2022-06-06T19:49:14 GMT+07:00" finished-at="2022-06-06T19:49:14 GMT+07:00">
          <reporter-output>
          </reporter-output>
        </test-method> <!-- test5 -->
        <test-method status="PASS" signature="test5()[pri:0, instance:online_tusur.unit_online_tusur.FactoryStydentTest@536aaa8d, instance params:[online_tusur.unit_online_tusur.Student@45820e51]]" name="test5" duration-ms="0" started-at="2022-06-06T19:49:14 GMT+07:00" finished-at="2022-06-06T19:49:14 GMT+07:00">
          <reporter-output>
          </reporter-output>
        </test-method> <!-- test5 -->
        <test-method status="PASS" signature="test5()[pri:0, instance:online_tusur.unit_online_tusur.FactoryStydentTest@59e5ddf, instance params:[online_tusur.unit_online_tusur.Student@7113b13f]]" name="test5" duration-ms="0" started-at="2022-06-06T19:49:14 GMT+07:00" finished-at="2022-06-06T19:49:14 GMT+07:00">
          <reporter-output>
          </reporter-output>
        </test-method> <!-- test5 -->
        <test-method status="FAIL" signature="test5()[pri:0, instance:online_tusur.unit_online_tusur.FactoryStydentTest@76f2b07d, instance params:[online_tusur.unit_online_tusur.Student@cb51256]]" name="test5" duration-ms="0" started-at="2022-06-06T19:49:14 GMT+07:00" finished-at="2022-06-06T19:49:14 GMT+07:00">
          <exception class="org.opentest4j.AssertionFailedError">
            <message>
              <![CDATA[expected: <Radiiiionov> but was: <Radionov>]]>
            </message>
            <full-stacktrace>
              <![CDATA[org.opentest4j.AssertionFailedError: expected: <Radiiiionov> but was: <Radionov>
at org.junit.jupiter.api.AssertionUtils.fail(AssertionUtils.java:55)
at org.junit.jupiter.api.AssertionUtils.failNotEqual(AssertionUtils.java:62)
at org.junit.jupiter.api.AssertEquals.assertEquals(AssertEquals.java:182)
at org.junit.jupiter.api.AssertEquals.assertEquals(AssertEquals.java:177)
at org.junit.jupiter.api.Assertions.assertEquals(Assertions.java:1124)
at online_tusur.unit_online_tusur.FactoryStydentTest.test5(FactoryStydentTest.java:58)
at sun.reflect.NativeMethodAccessorImpl.invoke0(Native Method)
at sun.reflect.NativeMethodAccessorImpl.invoke(Unknown Source)
at sun.reflect.DelegatingMethodAccessorImpl.invoke(Unknown Source)
at java.lang.reflect.Method.invoke(Unknown Source)
at org.testng.internal.MethodInvocationHelper.invokeMethod(MethodInvocationHelper.java:133)
at org.testng.internal.TestInvoker.invokeMethod(TestInvoker.java:598)
at org.testng.internal.TestInvoker.invokeTestMethod(TestInvoker.java:173)
at org.testng.internal.MethodRunner.runInSequence(MethodRunner.java:46)
at org.testng.internal.TestInvoker$MethodInvocationAgent.invoke(TestInvoker.java:824)
at org.testng.internal.TestInvoker.invokeTestMethods(TestInvoker.java:146)
at org.testng.internal.TestMethodWorker.invokeTestMethods(TestMethodWorker.java:146)
at org.testng.internal.TestMethodWorker.run(TestMethodWorker.java:128)
at java.util.ArrayList.forEach(Unknown Source)
at org.testng.TestRunner.privateRun(TestRunner.java:794)
at org.testng.TestRunner.run(TestRunner.java:596)
at org.testng.SuiteRunner.runTest(SuiteRunner.java:377)
at org.testng.SuiteRunner.runSequentially(SuiteRunner.java:371)
at org.testng.SuiteRunner.privateRun(SuiteRunner.java:332)
at org.testng.SuiteRunner.run(SuiteRunner.java:276)
at org.testng.SuiteRunnerWorker.runSuite(SuiteRunnerWorker.java:53)
at org.testng.SuiteRunnerWorker.run(SuiteRunnerWorker.java:96)
at org.testng.TestNG.runSuitesSequentially(TestNG.java:1212)
at org.testng.TestNG.runSuitesLocally(TestNG.java:1134)
at org.testng.TestNG.runSuites(TestNG.java:1063)
at org.testng.TestNG.run(TestNG.java:1031)
at org.testng.remote.AbstractRemoteTestNG.run(AbstractRemoteTestNG.java:115)
at org.testng.remote.RemoteTestNG.initAndRun(RemoteTestNG.java:251)
at org.testng.remote.RemoteTestNG.main(RemoteTestNG.java:77)
]]>
            </full-stacktrace>
          </exception> <!-- org.opentest4j.AssertionFailedError -->
          <reporter-output>
          </reporter-output>
        </test-method> <!-- test5 -->
        <test-method status="FAIL" signature="test5()[pri:0, instance:online_tusur.unit_online_tusur.FactoryStydentTest@e320068, instance params:[online_tusur.unit_online_tusur.Student@42d8062c]]" name="test5" duration-ms="0" started-at="2022-06-06T19:49:14 GMT+07:00" finished-at="2022-06-06T19:49:14 GMT+07:00">
          <exception class="org.opentest4j.AssertionFailedError">
            <message>
              <![CDATA[expected: <Radiiiionov> but was: <Radionov>]]>
            </message>
            <full-stacktrace>
              <![CDATA[org.opentest4j.AssertionFailedError: expected: <Radiiiionov> but was: <Radionov>
at org.junit.jupiter.api.AssertionUtils.fail(AssertionUtils.java:55)
at org.junit.jupiter.api.AssertionUtils.failNotEqual(AssertionUtils.java:62)
at org.junit.jupiter.api.AssertEquals.assertEquals(AssertEquals.java:182)
at org.junit.jupiter.api.AssertEquals.assertEquals(AssertEquals.java:177)
at org.junit.jupiter.api.Assertions.assertEquals(Assertions.java:1124)
at online_tusur.unit_online_tusur.FactoryStydentTest.test5(FactoryStydentTest.java:58)
at sun.reflect.NativeMethodAccessorImpl.invoke0(Native Method)
at sun.reflect.NativeMethodAccessorImpl.invoke(Unknown Source)
at sun.reflect.DelegatingMethodAccessorImpl.invoke(Unknown Source)
at java.lang.reflect.Method.invoke(Unknown Source)
at org.testng.internal.MethodInvocationHelper.invokeMethod(MethodInvocationHelper.java:133)
at org.testng.internal.TestInvoker.invokeMethod(TestInvoker.java:598)
at org.testng.internal.TestInvoker.invokeTestMethod(TestInvoker.java:173)
at org.testng.internal.MethodRunner.runInSequence(MethodRunner.java:46)
at org.testng.internal.TestInvoker$MethodInvocationAgent.invoke(TestInvoker.java:824)
at org.testng.internal.TestInvoker.invokeTestMethods(TestInvoker.java:146)
at org.testng.internal.TestMethodWorker.invokeTestMethods(TestMethodWorker.java:146)
at org.testng.internal.TestMethodWorker.run(TestMethodWorker.java:128)
at java.util.ArrayList.forEach(Unknown Source)
at org.testng.TestRunner.privateRun(TestRunner.java:794)
at org.testng.TestRunner.run(TestRunner.java:596)
at org.testng.SuiteRunner.runTest(SuiteRunner.java:377)
at org.testng.SuiteRunner.runSequentially(SuiteRunner.java:371)
at org.testng.SuiteRunner.privateRun(SuiteRunner.java:332)
at org.testng.SuiteRunner.run(SuiteRunner.java:276)
at org.testng.SuiteRunnerWorker.runSuite(SuiteRunnerWorker.java:53)
at org.testng.SuiteRunnerWorker.run(SuiteRunnerWorker.java:96)
at org.testng.TestNG.runSuitesSequentially(TestNG.java:1212)
at org.testng.TestNG.runSuitesLocally(TestNG.java:1134)
at org.testng.TestNG.runSuites(TestNG.java:1063)
at org.testng.TestNG.run(TestNG.java:1031)
at org.testng.remote.AbstractRemoteTestNG.run(AbstractRemoteTestNG.java:115)
at org.testng.remote.RemoteTestNG.initAndRun(RemoteTestNG.java:251)
at org.testng.remote.RemoteTestNG.main(RemoteTestNG.java:77)
]]>
            </full-stacktrace>
          </exception> <!-- org.opentest4j.AssertionFailedError -->
          <reporter-output>
          </reporter-output>
        </test-method> <!-- test5 -->
      </class> <!-- online_tusur.unit_online_tusur.FactoryStydentTest -->
    </test> <!-- Default test -->
  </suite> <!-- Default suite -->
</testng-results>
